Workbook

Sheet insurance orig
A1: age | B1: sex | C1: bmi | D1: children | E1: smoker | F1: region | G1: charges
A2: 19 | B2: female | C2: 27.9 | D2: 0 | E2: yes | F2: southwest | G2: 16884.924
A3: 18 | B3: male | C3: 33.77 | D3: 1 | E3: no | F3: southeast | G3: 1725.5523
A4: 28 | B4: male | C4: 33 | D4: 3 | E4: no | F4: southeast | G4: 4449.462
A5: 33 | B5: male | C5: 22.705 | D5: 0 | E5: no | F5: northwest | G5: 21984.471
A6: 32 | B6: male | C6: 28.88 | D6: 0 | E6: no | F6: northwest | G6: 3866.8552
A7: 31 | B7: female | C7: 25.74 | D7: 0 | E7: no | F7: southeast | G7: 3756.6216
A8: 46 | B8: female | C8: 33.44 | D8: 1 | E8: no | F8: southeast | G8: 8240.5896
A9: 37 | B9: female | C9: 27.74 | D9: 3 | E9: no | F9: northwest | G9: 7281.5056
A10: 37 | B10: male | C10: 29.83 | D10: 2 | E10: no | F10: northeast | G10: 6406.4107
A11: 60 | B11: female | C11: 25.84 | D11: 0 | E11: no | F11: northwest | G11: 28923.137
A12: 25 | B12: male | C12: 26.22 | D12: 0 | E12: no | F12: northeast | G12: 2721.3208
A13: 62 | B13: female | C13: 26.29 | D13: 0 | E13: yes | F13: southeast | G13: 27808.725
... A1339: 61 | B1339: female | C1339: 29.07 | D1339: 0 | E1339: yes | F1339: northwest | G1339: 29141.36

Sheet insurance olah
A1: age | B1: sex | C1: bmi | D1: children | E1: smoker | F1: region | G1: charges | H1: charges_class | I1: desc_charges_class | J1: charges_16,7K | K1: smoker_alias | L1: region_alias
A2: 19 | B2: female | C2: 27.9 | D2: 0 | E2: yes | F2: southwest | G2: 16884.924 | H2: {=INDEX(kelas_charges[kelas],MATCH(1,(insurance[[#This Row],[charges]]>=kelas_charges[Lower])*(insurance[[#This Row],[charges]]<kelas_charges[Upper]),0),1)} -> 3 | I2: {=INDEX(kelas_charges[desc],MATCH(1,(insurance[[#This Row],[charges]]>=kelas_charges[Lower])*(insurance[[#This Row],[charges]]<kelas_charges[Upper]),0),1)} -> 12512 s.d 18207 | J2: =IF(insurance[[#This Row],[charges]]>16700,1,0) -> 1 | K2: =IF(insurance[[#This Row],[smoker]]="yes",1,0) -> 1 | L2: =VLOOKUP(insurance[[#This Row],[region]],Table2[],2,0) -> 3
A3: 18 | B3: male | C3: 33.77 | D3: 1 | E3: no | F3: southeast | G3: 1725.5523 | H3: {=INDEX(kelas_charges[kelas],MATCH(1,(insurance[[#This Row],[charges]]>=kelas_charges[Lower])*(insurance[[#This Row],[charges]]<kelas_charges[Upper]),0),1)} -> 1 | I3: {=INDEX(kelas_charges[desc],MATCH(1,(insurance[[#This Row],[charges]]>=kelas_charges[Lower])*(insurance[[#This Row],[charges]]<kelas_charges[Upper]),0),1)} -> 1121 s.d 6817 | J3: =IF(insurance[[#This Row],[charges]]>16700,1,0) -> 0 | K3: =IF(insurance[[#This Row],[smoker]]="yes",1,0) -> 0 | L3: =VLOOKUP(insurance[[#This Row],[region]],Table2[],2,0) -> 4
A4: 28 | B4: male | C4: 33 | D4: 3 | E4: no | F4: southeast | G4: 4449.462 | H4: {=INDEX(kelas_charges[kelas],MATCH(1,(insurance[[#This Row],[charges]]>=kelas_charges[Lower])*(insurance[[#This Row],[charges]]<kelas_charges[Upper]),0),1)} -> 1 | I4: {=INDEX(kelas_charges[desc],MATCH(1,(insurance[[#This Row],[charges]]>=kelas_charges[Lower])*(insurance[[#This Row],[charges]]<kelas_charges[Upper]),0),1)} -> 1121 s.d 6817 | J4: =IF(insurance[[#This Row],[charges]]>16700,1,0) -> 0 | K4: =IF(insurance[[#This Row],[smoker]]="yes",1,0) -> 0 | L4: =VLOOKUP(insurance[[#This Row],[region]],Table2[],2,0) -> 4
A5: 33 | B5: male | C5: 22.705 | D5: 0 | E5: no | F5: northwest | G5: 21984.471 | H5: {=INDEX(kelas_charges[kelas],MATCH(1,(insurance[[#This Row],[charges]]>=kelas_charges[Lower])*(insurance[[#This Row],[charges]]<kelas_charges[Upper]),0),1)} -> 4 | I5: {=INDEX(kelas_charges[desc],MATCH(1,(insurance[[#This Row],[charges]]>=kelas_charges[Lower])*(insurance[[#This Row],[charges]]<kelas_charges[Upper]),0),1)} -> 18207 s.d 23903 | J5: =IF(insurance[[#This Row],[charges]]>16700,1,0) -> 1 | K5: =IF(insurance[[#This Row],[smoker]]="yes",1,0) -> 0 | L5: =VLOOKUP(insurance[[#This Row],[region]],Table2[],2,0) -> 1
A6: 32 | B6: male | C6: 28.88 | D6: 0 | E6: no | F6: northwest | G6: 3866.8552 | H6: {=INDEX(kelas_charges[kelas],MATCH(1,(insurance[[#This Row],[charges]]>=kelas_charges[Lower])*(insurance[[#This Row],[charges]]<kelas_charges[Upper]),0),1)} -> 1 | I6: {=INDEX(kelas_charges[desc],MATCH(1,(insurance[[#This Row],[charges]]>=kelas_charges[Lower])*(insurance[[#This Row],[charges]]<kelas_charges[Upper]),0),1)} -> 1121 s.d 6817 | J6: =IF(insurance[[#This Row],[charges]]>16700,1,0) -> 0 | K6: =IF(insurance[[#This Row],[smoker]]="yes",1,0) -> 0 | L6: =VLOOKUP(insurance[[#This Row],[region]],Table2[],2,0) -> 1
A7: 31 | B7: female | C7: 25.74 | D7: 0 | E7: no | F7: southeast | G7: 3756.6216 | H7: {=INDEX(kelas_charges[kelas],MATCH(1,(insurance[[#This Row],[charges]]>=kelas_charges[Lower])*(insurance[[#This Row],[charges]]<kelas_charges[Upper]),0),1)} -> 1 | I7: {=INDEX(kelas_charges[desc],MATCH(1,(insurance[[#This Row],[charges]]>=kelas_charges[Lower])*(insurance[[#This Row],[charges]]<kelas_charges[Upper]),0),1)} -> 1121 s.d 6817 | J7: =IF(insurance[[#This Row],[charges]]>16700,1,0) -> 0 | K7: =IF(insurance[[#This Row],[smoker]]="yes",1,0) -> 0 | L7: =VLOOKUP(insurance[[#This Row],[region]],Table2[],2,0) -> 4
A8: 46 | B8: female | C8: 33.44 | D8: 1 | E8: no | F8: southeast | G8: 8240.5896 | H8: {=INDEX(kelas_charges[kelas],MATCH(1,(insurance[[#This Row],[charges]]>=kelas_charges[Lower])*(insurance[[#This Row],[charges]]<kelas_charges[Upper]),0),1)} -> 2 | I8: {=INDEX(kelas_charges[desc],MATCH(1,(insurance[[#This Row],[charges]]>=kelas_charges[Lower])*(insurance[[#This Row],[charges]]<kelas_charges[Upper]),0),1)} -> 6817 s.d 12512 | J8: =IF(insurance[[#This Row],[charges]]>16700,1,0) -> 0 | K8: =IF(insurance[[#This Row],[smoker]]="yes",1,0) -> 0 | L8: =VLOOKUP(insurance[[#This Row],[region]],Table2[],2,0) -> 4
A9: 37 | B9: female | C9: 27.74 | D9: 3 | E9: no | F9: northwest | G9: 7281.5056 | H9: {=INDEX(kelas_charges[kelas],MATCH(1,(insurance[[#This Row],[charges]]>=kelas_charges[Lower])*(insurance[[#This Row],[charges]]<kelas_charges[Upper]),0),1)} -> 2 | I9: {=INDEX(kelas_charges[desc],MATCH(1,(insurance[[#This Row],[charges]]>=kelas_charges[Lower])*(insurance[[#This Row],[charges]]<kelas_charges[Upper]),0),1)} -> 6817 s.d 12512 | J9: =IF(insurance[[#This Row],[charges]]>16700,1,0) -> 0 | K9: =IF(insurance[[#This Row],[smoker]]="yes",1,0) -> 0 | L9: =VLOOKUP(insurance[[#This Row],[region]],Table2[],2,0) -> 1
A10: 37 | B10: male | C10: 29.83 | D10: 2 | E10: no | F10: northeast | G10: 6406.4107 | H10: {=INDEX(kelas_charges[kelas],MATCH(1,(insurance[[#This Row],[charges]]>=kelas_charges[Lower])*(insurance[[#This Row],[charges]]<kelas_charges[Upper]),0),1)} -> 1 | I10: {=INDEX(kelas_charges[desc],MATCH(1,(insurance[[#This Row],[charges]]>=kelas_charges[Lower])*(insurance[[#This Row],[charges]]<kelas_charges[Upper]),0),1)} -> 1121 s.d 6817 | J10: =IF(insurance[[#This Row],[charges]]>16700,1,0) -> 0 | K10: =IF(insurance[[#This Row],[smoker]]="yes",1,0) -> 0 | L10: =VLOOKUP(insurance[[#This Row],[region]],Table2[],2,0) -> 2
A11: 60 | B11: female | C11: 25.84 | D11: 0 | E11: no | F11: northwest | G11: 28923.137 | H11: {=INDEX(kelas_charges[kelas],MATCH(1,(insurance[[#This Row],[charges]]>=kelas_charges[Lower])*(insurance[[#This Row],[charges]]<kelas_charges[Upper]),0),1)} -> 5 | I11: {=INDEX(kelas_charges[desc],MATCH(1,(insurance[[#This Row],[charges]]>=kelas_charges[Lower])*(insurance[[#This Row],[charges]]<kelas_charges[Upper]),0),1)} -> 23903 s.d 29598 | J11: =IF(insurance[[#This Row],[charges]]>16700,1,0) -> 1 | K11: =IF(insurance[[#This Row],[smoker]]="yes",1,0) -> 0 | L11: =VLOOKUP(insurance[[#This Row],[region]],Table2[],2,0) -> 1
A12: 25 | B12: male | C12: 26.22 | D12: 0 | E12: no | F12: northeast | G12: 2721.3208 | H12: {=INDEX(kelas_charges[kelas],MATCH(1,(insurance[[#This Row],[charges]]>=kelas_charges[Lower])*(insurance[[#This Row],[charges]]<kelas_charges[Upper]),0),1)} -> 1 | I12: {=INDEX(kelas_charges[desc],MATCH(1,(insurance[[#This Row],[charges]]>=kelas_charges[Lower])*(insurance[[#This Row],[charges]]<kelas_charges[Upper]),0),1)} -> 1121 s.d 6817 | J12: =IF(insurance[[#This Row],[charges]]>16700,1,0) -> 0 | K12: =IF(insurance[[#This Row],[smoker]]="yes",1,0) -> 0 | L12: =VLOOKUP(insurance[[#This Row],[region]],Table2[],2,0) -> 2
A13: 62 | B13: female | C13: 26.29 | D13: 0 | E13: yes | F13: southeast | G13: 27808.725 | H13: {=INDEX(kelas_charges[kelas],MATCH(1,(insurance[[#This Row],[charges]]>=kelas_charges[Lower])*(insurance[[#This Row],[charges]]<kelas_charges[Upper]),0),1)} -> 5 | I13: {=INDEX(kelas_charges[desc],MATCH(1,(insurance[[#This Row],[charges]]>=kelas_charges[Lower])*(insurance[[#This Row],[charges]]<kelas_charges[Upper]),0),1)} -> 23903 s.d 29598 | J13: =IF(insurance[[#This Row],[charges]]>16700,1,0) -> 1 | K13: =IF(insurance[[#This Row],[smoker]]="yes",1,0) -> 1 | L13: =VLOOKUP(insurance[[#This Row],[region]],Table2[],2,0) -> 4
... A1339: 61 | B1339: female | C1339: 29.07 | D1339: 0 | E1339: yes | F1339: northwest | G1339: 29141.36 | H1339: {=INDEX(kelas_charges[kelas],MATCH(1,(insurance[[#This Row],[charges]]>=kelas_charges[Lower])*(insurance[[#This Row],[charges]]<kelas_charges[Upper]),0),1)} -> 5 | I1339: {=INDEX(kelas_charges[desc],MATCH(1,(insurance[[#This Row],[charges]]>=kelas_charges[Lower])*(insurance[[#This Row],[charges]]<kelas_charges[Upper]),0),1)} -> 23903 s.d 29598 | J1339: =IF(insurance[[#This Row],[charges]]>16700,1,0) -> 1 | K1339: =IF(insurance[[#This Row],[smoker]]="yes",1,0) -> 1 | L1339: =VLOOKUP(insurance[[#This Row],[region]],Table2[],2,0) -> 1

Sheet Langkah #1
A1: Langkah #1 - Analisa Descriptive Statistic
A2: No | B2: Item | C2: Hasil | D2: Keterangan
A3: 1 | B3: Rata-rata umur pengguna | C3: =AVERAGE(insurance[age]) -> 39.207025 | K3: 6 | L3: Rata rata umur perempuan dan laki-laki yang merokok
A4: 2 | B4: Rata-rata nilai BMI dari pengguna yang merokok | C4: =AVERAGEIFS(insurance[bmi],insurance[smoker],"yes") -> 30.708449 | L4: female | M4: =AVERAGEIFS(insurance[age],insurance[sex],'Langkah #1'!L4,insurance[smoker],"yes") -> 38.608696
A5: 3 | B5: Berapa rata rata umur pada data tersebut? | C5: =AVERAGEIFS(insurance[age],insurance[smoker],"yes") -> 38.514599 | L5: male | M5: =AVERAGEIFS(insurance[age],insurance[sex],'Langkah #1'!L5,insurance[smoker],"yes") -> 38.446541
A6: 4 | B6: Berapa rata rata nilai BMI dari yang merokok? | C6: =C4 -> 30.708449 | E6: perokok; non perokok | F6: =SUMIFS(insurance[bmi],insurance[smoker],"yes")/COUNTIF(insurance[smoker],"yes") -> 30.708449 | G6: =SUMIFS(insurance[bmi],insurance[smoker],"no")/COUNTIF(insurance[smoker],"no") -> 30.651795 | K6: 7 | L6: Rata rata tagihan kesehatan perokok atau non merokok
A7: 5 | B7: Apakah variansi dari data charges perokok dan non perokok sama? | L7: perokok | M7: =AVERAGEIFS(insurance[charges],insurance[smoker],"yes") -> 32050.232 | N7: =M7/M8 -> 3.8000015
A8: 6 | B8: Apakah rata rata umur perempuan dan laki-laki yang merokok sama? | C8: =M4=M5 -> FALSE | E8: wanita; pria | F8: =SUMIFS(insurance[age],insurance[sex],"female",insurance[smoker],"yes")/COUNTIFS(insurance[sex],"female",insurance[smoker],"yes") -> 38.608696 | G8: =SUMIFS(insurance[age],insurance[sex],"male",insurance[smoker],"yes")/COUNTIFS(insurance[sex],"male",insurance[smoker],"yes") -> 38.446541 | L8: non perokok | M8: =AVERAGEIFS(insurance[charges],insurance[smoker],"no") -> 8434.2683
A9: 7 | B9: Mana yang lebih tinggi, rata rata tagihan kesehatan perokok atau non merokok? | C9: Lebih tinggi perokok | E9: perokok; non perokok | F9: =SUMIFS(insurance[charges],insurance[smoker],"yes")/COUNTIF(insurance[smoker],"yes") -> 32050.232 | G9: =SUMIFS(insurance[charges],insurance[smoker],"no")/COUNTIF(insurance[smoker],"no") -> 8434.2683 | K9: 8 | L9: Rata rata tagihan kesehatan perokok yang BMI nya diatas 25 atau non perokok yang BMI nya diatas 25
A10: 8 | B10: Mana yang lebih tinggi, rata rata tagihan kesehatan perokok yang BMI nya diatas 25 atau non perokok yang BMI nya diatas 25 | C10: Lebih tinggi perokok dengan bmi>25 | E10: perokok & bmi>25; non perokok & bmi>25 | F10: =SUMIFS(insurance[charges],insurance[smoker],"yes",insurance[bmi],">"&25)/COUNTIFS(insurance[smoker],"yes",insurance[bmi],">"&25) -> 35116.91 | G10: =SUMIFS(insurance[charges],insurance[smoker],"no",insurance[bmi],">"&25)/COUNTIFS(insurance[smoker],"no",insurance[bmi],">"&25) -> 8629.5896 | H10: bmi >25 | I10: =SUMIFS(insurance[charges],insurance[bmi],">"&25)/COUNTIFS(insurance[bmi],">"&25) -> 13946.476 | L10: perokok | M10: =AVERAGEIFS(insurance[charges],insurance[smoker],"yes",insurance[bmi],">"&25) -> 35116.91 | N10: all | O10: =AVERAGE(insurance[charges]) -> 13270.422 | P10: bmi>25 | Q10: =AVERAGEIFS(insurance[charges],insurance[bmi],">"&25) -> 13946.476
A11: 9 | B11: BMI mana yang lebih tinggi, seseorang laki-laki atau perempuan? | C11: Lebih tinggi laki-laki | E11: laki-laki; perempuan | F11: =SUMIFS(insurance[bmi],insurance[sex],"male")/COUNTIF(insurance[sex],"male") -> 30.943129 | G11: =SUMIFS(insurance[bmi],insurance[sex],"female")/COUNTIF(insurance[sex],"female") -> 30.377749 | L11: non perokok | M11: =AVERAGEIFS(insurance[charges],insurance[smoker],"no",insurance[bmi],">"&25) -> 8629.5896 | N11: =M10/M11 -> 4.0693603 | P11: bmi<=25 | Q11: =AVERAGEIFS(insurance[charges],insurance[bmi],"<="&25) -> 10284.29
A12: 10 | B12: BMI mana yang lebih tinggi, seseorang perokok atau non perokok? | C12: relatif sama | E12: perokok; non perokok | F12: =SUMIFS(insurance[bmi],insurance[smoker],"yes")/COUNTIF(insurance[smoker],"yes") -> 30.708449 | G12: =SUMIFS(insurance[bmi],insurance[smoker],"no")/COUNTIF(insurance[smoker],"no") -> 30.651795 | K12: 9-10 | L12: Rata-rata bmi
L13: perokok | M13: =AVERAGEIFS(insurance[bmi],insurance[smoker],"yes") -> 30.708449 | N13: female | O13: =AVERAGEIFS(insurance[bmi],insurance[sex],'Langkah #1'!N13) -> 30.377749
A14: 11 | B14: female | C14: =COUNTIFS(insurance[sex],'Langkah #1'!B14)/COUNT(insurance[age]) -> 0.49476831 | L14: non perokok | M14: =AVERAGEIFS(insurance[bmi],insurance[smoker],"no") -> 30.651795 | N14: male | O14: =AVERAGEIFS(insurance[bmi],insurance[sex],'Langkah #1'!N14) -> 30.943129
B15: male | C15: =1-C14 -> 0.50523169
K16: 3 | L16: avg umur
L17: perokok | M17: =AVERAGEIFS(insurance[age],insurance[smoker],"yes") -> 38.514599 | N17: female | O17: =AVERAGEIFS(insurance[age],insurance[sex],$N17) -> 39.503021
L18: non perokok | M18: =AVERAGEIFS(insurance[age],insurance[smoker],"no") -> 39.385338 | N18: male | O18: =AVERAGEIFS(insurance[age],insurance[sex],$N18) -> 38.91716

Sheet Langkah #2 (2)
I2: Langkah #2 - Analisa Variabel Kontinu | AM2: Nilai rata-rata tagihan per-wilayah (charges) | AP2: dalam $
B3: 1 | C3: Gender mana yang memiliki tagihan paling tinggi? | AE3: distribusi peluang tagihan per-region | AM3: northwest | AN3: northeast | AO3: southwest | AP3: southeast
B4: 2 | C4: Distribusi peluang tagihan di tiap-tiap region | I4: Item | J4: Northeast | K4: Northwest | L4: Southeast | M4: Southwest | N4: Total | AE4: class | AF4: bin | AG4: northwest | AH4: northeast | AI4: southwest | AJ4: southeast | AM4: =AVERAGEIFS(insurance[charges],insurance[region],'Langkah #2 (2)'!AM3) -> 12417.575 | AN4: =AVERAGEIFS(insurance[charges],insurance[region],'Langkah #2 (2)'!AN3) -> 13406.385 | AO4: =AVERAGEIFS(insurance[charges],insurance[region],'Langkah #2 (2)'!AO3) -> 12346.937 | AP4: =AVERAGEIFS(insurance[charges],insurance[region],'Langkah #2 (2)'!AP3) -> 14735.411
B5: 3 | C5: Apakah setiap region memiliki proporsi data banyak orang yang sama? | I5: Peluang pengguna | J5: =COUNTIFS(insurance[region],'Langkah #2 (2)'!J$4)/COUNT(insurance[age]) -> 0.24215247 | K5: =COUNTIFS(insurance[region],'Langkah #2 (2)'!K$4)/COUNT(insurance[age]) -> 0.24289985 | L5: =COUNTIFS(insurance[region],'Langkah #2 (2)'!L$4)/COUNT(insurance[age]) -> 0.27204783 | M5: =COUNTIFS(insurance[region],'Langkah #2 (2)'!M$4)/COUNT(insurance[age]) -> 0.24289985 | N5: =SUM(J5:M5) -> 1 | AE5: 1 | AF5: =VLOOKUP(AE5,kelas_charges[[kelas]:[desc]],4,0) -> 1121 s.d 6817 | AG5: =L24 -> #DIV/0! | AH5: =L38 -> #DIV/0! | AI5: =L52 -> #DIV/0! | AJ5: =L66 -> #DIV/0! | AM5: =AM4/10^3 -> 12.417575 | AN5: =AN4/10^3 -> 13.406385 | AO5: =AO4/10^3 -> 12.346937 | AP5: =AP4/10^3 -> 14.735411
B6: 4 | C6: Mana yang lebih tinggi proporsi perokok atau non perokok? | I6: Peluang pengguna perokok dan non perokok | AE6: 2 | AF6: =VLOOKUP(AE6,kelas_charges[[kelas]:[desc]],4,0) -> 6817 s.d 12512 | AG6: =L25 -> #DIV/0! | AH6: =L39 -> #DIV/0! | AI6: =L53 -> #DIV/0! | AJ6: =L67 -> #DIV/0! | AL6: =SUM(AG5:AG6) -> #DIV/0! | AM6: =SUM(AH5:AH6) -> #DIV/0! | AN6: =SUM(AI5:AI6) -> #DIV/0! | AO6: =SUM(AJ5:AJ6) -> #DIV/0!
C7: - perokok | I7: perokok | J7: =COUNTIFS(insurance[smoker],"yes",insurance[region],'Langkah #2 (2)'!J$4)/COUNTIFS(insurance[region],'Langkah #2 (2)'!J$4) -> 0.20679012 | K7: =COUNTIFS(insurance[smoker],"yes",insurance[region],'Langkah #2 (2)'!K$4)/COUNTIFS(insurance[region],'Langkah #2 (2)'!K$4) -> 0.17846154 | L7: =COUNTIFS(insurance[smoker],"yes",insurance[region],'Langkah #2 (2)'!L$4)/COUNTIFS(insurance[region],'Langkah #2 (2)'!L$4) -> 0.25 | M7: =COUNTIFS(insurance[smoker],"yes",insurance[region],'Langkah #2 (2)'!M$4)/COUNTIFS(insurance[region],'Langkah #2 (2)'!M$4) -> 0.17846154 | N7: =COUNTIFS(insurance[smoker],"yes")/COUNT(insurance[age]) -> 0.20478326 | AE7: 3 | AF7: =VLOOKUP(AE7,kelas_charges[[kelas]:[desc]],4,0) -> 12512 s.d 18207 | AG7: =L26 -> #DIV/0! | AH7: =L40 -> #DIV/0! | AI7: =L54 -> #DIV/0! | AJ7: =L68 -> #DIV/0! | AL7: =1-AL6 -> #DIV/0! | AM7: =1-AM6 -> #DIV/0! | AN7: =1-AN6 -> #DIV/0! | AO7: =1-AO6 -> #DIV/0!
C8: - non perokok | I8: non perokok | J8: =1-J7 -> 0.79320988 | K8: =1-K7 -> 0.82153846 | L8: =1-L7 -> 0.75 | M8: =1-M7 -> 0.82153846 | N8: =1-N7 -> 0.79521674 | AE8: 4 | AF8: =VLOOKUP(AE8,kelas_charges[[kelas]:[desc]],4,0) -> 18207 s.d 23903 | AG8: =L27 -> #DIV/0! | AH8: =L41 -> #DIV/0! | AI8: =L55 -> #DIV/0! | AJ8: =L69 -> #DIV/0!
B9: 5 | C9: Berapa peluang seseorang tersebut adalah perempuan diketahui dia adalah perokok? | I9: Peluang perempuan/laki-laki adalah perokok | AE9: 5 | AF9: =VLOOKUP(AE9,kelas_charges[[kelas]:[desc]],4,0) -> 23903 s.d 29598 | AG9: =L28 -> #DIV/0! | AH9: =L42 -> #DIV/0! | AI9: =L56 -> #DIV/0! | AJ9: =L70 -> #DIV/0!
B10: 6 | C10: Berapa peluang seseorang tersebut adalah laki-laki diketahui dia adalah perokok? | I10: perempuan ∩ perokok | J10: =COUNTIFS(insurance[smoker],"yes",insurance[region],'Langkah #2 (2)'!J$4,insurance[sex],"female")/COUNTIFS(insurance[region],'Langkah #2 (2)'!J$4) -> 0.089506173 | K10: =COUNTIFS(insurance[smoker],"yes",insurance[region],'Langkah #2 (2)'!K$4,insurance[sex],"female")/COUNTIFS(insurance[region],'Langkah #2 (2)'!K$4) -> 0.089230769 | L10: =COUNTIFS(insurance[smoker],"yes",insurance[region],'Langkah #2 (2)'!L$4,insurance[sex],"female")/COUNTIFS(insurance[region],'Langkah #2 (2)'!L$4) -> 0.098901099 | M10: =COUNTIFS(insurance[smoker],"yes",insurance[region],'Langkah #2 (2)'!M$4,insurance[sex],"female")/COUNTIFS(insurance[region],'Langkah #2 (2)'!M$4) -> 0.064615385 | N10: =COUNTIFS(insurance[smoker],"yes",insurance[sex],"female")/COUNT(insurance[age]) -> 0.085949178 | AE10: 6 | AF10: =VLOOKUP(AE10,kelas_charges[[kelas]:[desc]],4,0) -> 29598 s.d 35293 | AG10: =L29 -> #DIV/0! | AH10: =L43 -> #DIV/0! | AI10: =L57 -> #DIV/0! | AJ10: =L71 -> #DIV/0!
B11: 7 | C11: Bagaimana bentuk distribusi peluang besar tagihan dari tiap-tiap region? | I11: laki-laki ∩ perokok | J11: =COUNTIFS(insurance[smoker],"yes",insurance[region],'Langkah #2 (2)'!J$4,insurance[sex],"male")/COUNTIFS(insurance[region],'Langkah #2 (2)'!J$4) -> 0.11728395 | K11: =COUNTIFS(insurance[smoker],"yes",insurance[region],'Langkah #2 (2)'!K$4,insurance[sex],"male")/COUNTIFS(insurance[region],'Langkah #2 (2)'!K$4) -> 0.089230769 | L11: =COUNTIFS(insurance[smoker],"yes",insurance[region],'Langkah #2 (2)'!L$4,insurance[sex],"male")/COUNTIFS(insurance[region],'Langkah #2 (2)'!L$4) -> 0.1510989 | M11: =COUNTIFS(insurance[smoker],"yes",insurance[region],'Langkah #2 (2)'!M$4,insurance[sex],"male")/COUNTIFS(insurance[region],'Langkah #2 (2)'!M$4) -> 0.11384615 | N11: =COUNTIFS(insurance[smoker],"yes",insurance[sex],"male")/COUNT(insurance[age]) -> 0.11883408 | AE11: 7 | AF11: =VLOOKUP(AE11,kelas_charges[[kelas]:[desc]],4,0) -> 35293 s.d 40989 | AG11: =L30 -> #DIV/0! | AH11: =L44 -> #DIV/0! | AI11: =L58 -> #DIV/0! | AJ11: =L72 -> #DIV/0!
C12: - Kurtosis | I12: Peluang perempuan/laki-laki jika diketahui perokok | AE12: 8 | AF12: =VLOOKUP(AE12,kelas_charges[[kelas]:[desc]],4,0) -> 40989 s.d 46684 | AG12: =L31 -> #DIV/0! | AH12: =L45 -> #DIV/0! | AI12: =L59 -> #DIV/0! | AJ12: =L73 -> #DIV/0!
C13: - Skewness | I13: p (perempuan|perokok) | J13: =J10/J$7 -> 0.43283582 | K13: =K10/K$7 -> 0.5 | L13: =L10/L$7 -> 0.3956044 | M13: =M10/M$7 -> 0.36206897 | N13: =N10/N$7 -> 0.41970803 | AE13: 9 | AF13: =VLOOKUP(AE13,kelas_charges[[kelas]:[desc]],4,0) -> 46684 s.d 52379 | AG13: =L32 -> #DIV/0! | AH13: =L46 -> #DIV/0! | AI13: =L60 -> #DIV/0! | AJ13: =L74 -> #DIV/0!
I14: p (laki-laki|perokok) | J14: =J11/J$7 -> 0.56716418 | K14: =K11/K$7 -> 0.5 | L14: =L11/L$7 -> 0.6043956 | M14: =M11/M$7 -> 0.63793103 | N14: =N11/N$7 -> 0.58029197 | AE14: 10 | AF14: =VLOOKUP(AE14,kelas_charges[[kelas]:[desc]],4,0) -> 52379 s.d 58075 | AG14: =L33 -> #DIV/0! | AH14: =L47 -> #DIV/0! | AI14: =L61 -> #DIV/0! | AJ14: =L75 -> #DIV/0!
AE15: 11 | AF15: =VLOOKUP(AE15,kelas_charges[[kelas]:[desc]],4,0) -> 58075 s.d 63771 | AG15: =L34 -> #DIV/0! | AH15: =L48 -> #DIV/0! | AI15: =L62 -> #DIV/0! | AJ15: =L76 -> #DIV/0!
AE17: Class
AE18: Mean | AG18: =AVERAGEIFS(insurance[charges_class],insurance[region],'Langkah #2 (2)'!AG$4) -> 2.4923077 | AH18: =AVERAGEIFS(insurance[charges_class],insurance[region],'Langkah #2 (2)'!AH$4) -> 2.6944444 | AI18: =AVERAGEIFS(insurance[charges_class],insurance[region],'Langkah #2 (2)'!AI$4) -> 2.5138462 | AJ18: =AVERAGEIFS(insurance[charges_class],insurance[region],'Langkah #2 (2)'!AJ$4) -> 2.9505495
AE19: Modus | AG19: =J24 -> 1 | AH19: =AG19 -> 1 | AI19: =AH19 -> 1 | AJ19: =AI19 -> 1
AE20: Median
AE21: Skew | AG21: =SKEW(AG5:AG15) -> #DIV/0! | AH21: =SKEW(AH5:AH15) -> #DIV/0! | AI21: =SKEW(AI5:AI15) -> #DIV/0! | AJ21: =SKEW(AJ5:AJ15) -> #DIV/0!
I22: northwest
I23: desc | J23: class | K23: freq | L23: peluang
D24: =COUNTIFS(insurance[region],"northwest") -> 325 | I24: 1121 s.d 6817 | J24: 1 | K24: =COUNTIFS(insurance[charges_class],Table912411[[#This Row],[class]],insurance[region],'Langkah #2'!$I$22) -> 0 | L24: =Table912411[[#This Row],[freq]]/SUM(Table912411[freq]) -> #DIV/0!
I25: 6817 s.d 12512 | J25: 2 | K25: =COUNTIFS(insurance[charges_class],Table912411[[#This Row],[class]],insurance[region],'Langkah #2'!$I$22) -> 0 | L25: =Table912411[[#This Row],[freq]]/SUM(Table912411[freq]) -> #DIV/0!
I26: 12512 s.d 18207 | J26: 3 | K26: =COUNTIFS(insurance[charges_class],Table912411[[#This Row],[class]],insurance[region],'Langkah #2'!$I$22) -> 0 | L26: =Table912411[[#This Row],[freq]]/SUM(Table912411[freq]) -> #DIV/0!
I27: 18207 s.d 23903 | J27: 4 | K27: =COUNTIFS(insurance[charges_class],Table912411[[#This Row],[class]],insurance[region],'Langkah #2'!$I$22) -> 0 | L27: =Table912411[[#This Row],[freq]]/SUM(Table912411[freq]) -> #DIV/0!
I28: 23903 s.d 29598 | J28: 5 | K28: =COUNTIFS(insurance[charges_class],Table912411[[#This Row],[class]],insurance[region],'Langkah #2'!$I$22) -> 0 | L28: =Table912411[[#This Row],[freq]]/SUM(Table912411[freq]) -> #DIV/0!
I29: 29598 s.d 35293 | J29: 6 | K29: =COUNTIFS(insurance[charges_class],Table912411[[#This Row],[class]],insurance[region],'Langkah #2'!$I$22) -> 0 | L29: =Table912411[[#This Row],[freq]]/SUM(Table912411[freq]) -> #DIV/0!
I30: 35293 s.d 40989 | J30: 7 | K30: =COUNTIFS(insurance[charges_class],Table912411[[#This Row],[class]],insurance[region],'Langkah #2'!$I$22) -> 0 | L30: =Table912411[[#This Row],[freq]]/SUM(Table912411[freq]) -> #DIV/0!
I31: 40989 s.d 46684 | J31: 8 | K31: =COUNTIFS(insurance[charges_class],Table912411[[#This Row],[class]],insurance[region],'Langkah #2'!$I$22) -> 0 | L31: =Table912411[[#This Row],[freq]]/SUM(Table912411[freq]) -> #DIV/0!
I32: 46684 s.d 52379 | J32: 9 | K32: =COUNTIFS(insurance[charges_class],Table912411[[#This Row],[class]],insurance[region],'Langkah #2'!$I$22) -> 0 | L32: =Table912411[[#This Row],[freq]]/SUM(Table912411[freq]) -> #DIV/0!
I33: 52379 s.d 58075 | J33: 10 | K33: =COUNTIFS(insurance[charges_class],Table912411[[#This Row],[class]],insurance[region],'Langkah #2'!$I$22) -> 0 | L33: =Table912411[[#This Row],[freq]]/SUM(Table912411[freq]) -> #DIV/0!
I34: 58075 s.d 63771 | J34: 11 | K34: =COUNTIFS(insurance[charges_class],Table912411[[#This Row],[class]],insurance[region],'Langkah #2'!$I$22) -> 0 | L34: =Table912411[[#This Row],[freq]]/SUM(Table912411[freq]) -> #DIV/0!
I36: northeast
I37: desc | J37: class | K37: freq | L37: peluang
I38: 1121 s.d 6817 | J38: 1 | K38: =COUNTIFS(insurance[charges_class],Table9124512[[#This Row],[class]],insurance[region],'Langkah #2'!$I$36) -> 0 | L38: =Table9124512[[#This Row],[freq]]/SUM(Table9124512[freq]) -> #DIV/0!
I39: 6817 s.d 12512 | J39: 2 | K39: =COUNTIFS(insurance[charges_class],Table9124512[[#This Row],[class]],insurance[region],'Langkah #2'!$I$36) -> 0 | L39: =Table9124512[[#This Row],[freq]]/SUM(Table9124512[freq]) -> #DIV/0!
I40: 12512 s.d 18207 | J40: 3 | K40: =COUNTIFS(insurance[charges_class],Table9124512[[#This Row],[class]],insurance[region],'Langkah #2'!$I$36) -> 0 | L40: =Table9124512[[#This Row],[freq]]/SUM(Table9124512[freq]) -> #DIV/0!
I41: 18207 s.d 23903 | J41: 4 | K41: =COUNTIFS(insurance[charges_class],Table9124512[[#This Row],[class]],insurance[region],'Langkah #2'!$I$36) -> 0 | L41: =Table9124512[[#This Row],[freq]]/SUM(Table9124512[freq]) -> #DIV/0!
I42: 23903 s.d 29598 | J42: 5 | K42: =COUNTIFS(insurance[charges_class],Table9124512[[#This Row],[class]],insurance[region],'Langkah #2'!$I$36) -> 0 | L42: =Table9124512[[#This Row],[freq]]/SUM(Table9124512[freq]) -> #DIV/0!
I43: 29598 s.d 35293 | J43: 6 | K43: =COUNTIFS(insurance[charges_class],Table9124512[[#This Row],[class]],insurance[region],'Langkah #2'!$I$36) -> 0 | L43: =Table9124512[[#This Row],[freq]]/SUM(Table9124512[freq]) -> #DIV/0!
...

Sheet Langkah #2
J5: Langkah #2 - Analisa Variabel Kontinu | AV5: Nilai rata-rata tagihan per-wilayah (charges) | AY5: dalam $
B6: 1 | C6: Gender mana yang memiliki tagihan paling tinggi? | AN6: distribusi peluang tagihan per-region | AV6: northwest | AW6: northeast | AX6: southwest | AY6: southeast | BB6: southwest | BC6: southeast | BD6: northwest | BE6: northeast | BH6: southwest | BI6: southeast | BJ6: northwest | BK6: northeast
B7: 2 | C7: Distribusi peluang tagihan di tiap-tiap region | J7: Item | K7: Northeast | L7: Northwest | M7: Southeast | N7: Southwest | AN7: class | AO7: bin | AP7: northwest | AQ7: northeast | AR7: southwest | AS7: southeast | AV7: =AVERAGEIFS(insurance[charges],insurance[region],'Langkah #2'!AV6) -> 12417.575 | AW7: =AVERAGEIFS(insurance[charges],insurance[region],'Langkah #2'!AW6) -> 13406.385 | AX7: =AVERAGEIFS(insurance[charges],insurance[region],'Langkah #2'!AX6) -> 12346.937 | AY7: =AVERAGEIFS(insurance[charges],insurance[region],'Langkah #2'!AY6) -> 14735.411 | BB7: 16884.924 | BC7: 1725.5523 | BD7: 21984.471 | BE7: 6406.4107 | BH7: 3 | BI7: 1 | BJ7: 4 | BK7: 1
B8: 3 | C8: Apakah setiap region memiliki proporsi data banyak orang yang sama? | J8: Proporsi pengguna | K8: =COUNTIFS(insurance[region],'Langkah #2'!K$7)/COUNT(insurance[age]) -> 0.24215247 | L8: =COUNTIFS(insurance[region],'Langkah #2'!L$7)/COUNT(insurance[age]) -> 0.24289985 | M8: =COUNTIFS(insurance[region],'Langkah #2'!M$7)/COUNT(insurance[age]) -> 0.27204783 | N8: =COUNTIFS(insurance[region],'Langkah #2'!N$7)/COUNT(insurance[age]) -> 0.24289985 | P8: =M8-N8 -> 0.029147982 | AN8: 1 | AO8: =VLOOKUP(AN8,kelas_charges[[kelas]:[desc]],4,0) -> 1121 s.d 6817 | AP8: =M27 -> 0.38461538 | AQ8: =M41 -> 0.32098765 | AR8: =M55 -> 0.37846154 | AS8: =M69 -> 0.38461538 | AV8: =AV7/10^3 -> 12.417575 | AW8: =AW7/10^3 -> 13.406385 | AX8: =AX7/10^3 -> 12.346937 | AY8: =AY7/10^3 -> 14.735411 | BB8: 1826.843 | BC8: 4449.462 | BD8: 3866.8552 | BE8: 2721.3208 | BH8: 1 | BI8: 1 | BJ8: 1 | BK8: 1
B9: 4 | C9: Mana yang lebih tinggi proporsi perokok atau non perokok? | AN9: 2 | AO9: =VLOOKUP(AN9,kelas_charges[[kelas]:[desc]],4,0) -> 6817 s.d 12512 | AP9: =M28 -> 0.29846154 | AQ9: =M42 -> 0.29320988 | AR9: =M56 -> 0.32923077 | AS9: =M70 -> 0.23076923 | AU9: =SUM(AP8:AP9) -> 0.68307692 | AV9: =SUM(AQ8:AQ9) -> 0.61419753 | AW9: =SUM(AR8:AR9) -> 0.70769231 | AX9: =SUM(AS8:AS9) -> 0.61538462 | BB9: 1837.237 | BC9: 3756.6216 | BD9: 7281.5056 | BE9: 10797.336 | BH9: 1 | BI9: 1 | BJ9: 2 | BK9: 2
C10: - perokok | AN10: 3 | AO10: =VLOOKUP(AN10,kelas_charges[[kelas]:[desc]],4,0) -> 12512 s.d 18207 | AP10: =M29 -> 0.11076923 | AQ10: =M43 -> 0.15432099 | AR10: =M57 -> 0.098461538 | AS10: =M71 -> 0.093406593 | AU10: =1-AU9 -> 0.31692308 | AV10: =1-AV9 -> 0.38580247 | AW10: =1-AW9 -> 0.29230769 | AX10: =1-AX9 -> 0.38461538 | BB10: 10602.385 | BC10: 8240.5896 | BD10: 28923.137 | BE10: 2395.1716 | BH10: 2 | BI10: 2 | BJ10: 5 | BK10: 1 | CE10: southwest | CF10: southeast | CG10: northwest | CH10: northeast | CL10: southwest | CM10: southeast | CN10: northwest | CO10: northeast
C11: - non perokok | J11: Peluang pengguna perokok dan non perokok | AJ11: 4 | AK11: =VLOOKUP(AJ11,kelas_charges[[kelas]:[desc]],4,0) -> 18207 s.d 23903 | AL11: =M30 -> 0.061538462 | AM11: =M44 -> 0.080246914 | AN11: =M58 -> 0.058461538 | AO11: =M72 -> 0.076923077 | AX11: 36837.467 | AY11: 27808.725 | AZ11: 6203.9017 | BA11: 13228.847 | BD11: 7 | BE11: 5 | BF11: 1 | BG11: 3 | BZ11: avg | CA11: =AVERAGE(BH7:BH331) -> 2.4398734 | CB11: =AVERAGE(BI7:BI370) -> 2.9577465 | CC11: =AVERAGE(BJ7:BJ331) -> 2.5158228 | CD11: =AVERAGE(BK7:BK330) -> 2.6920635 | CG11: avg | CH11: =AVERAGE(BB7:BB331) -> 11931.907 | CI11: =AVERAGE(BC7:BC370) -> 14760.21 | CJ11: =AVERAGE(BD7:BD331) -> 12210.173 | CK11: =AVERAGE(BE7:BE330) -> 13029.652
B12: 5 | C12: Berapa peluang seseorang tersebut adalah perempuan diketahui dia adalah perokok? | J12: perokok | K12: =COUNTIFS(insurance[smoker],"yes")/COUNT(insurance[age]) -> 0.20478326 | AJ12: 5 | AK12: =VLOOKUP(AJ12,kelas_charges[[kelas]:[desc]],4,0) -> 23903 s.d 29598 | AL12: =M31 -> 0.055384615 | AM12: =M45 -> 0.043209877 | AN12: =M59 -> 0.021538462 | AO12: =M73 -> 0.046703297 | AX12: 4149.736 | AY12: 11090.718 | AZ12: 12268.632 | BA12: 37701.877 | BD12: 1 | BE12: 2 | BF12: 2 | BG12: 7 | BZ12: med | CA12: =MEDIAN(BH7:BH331) -> 2 | CB12: =MEDIAN(BI7:BI370) -> 2 | CC12: =MEDIAN(BJ7:BJ331) -> 2 | CD12: =MEDIAN(BK7:BK330) -> 2 | CG12: med | CH12: =MEDIAN(BB7:BB331) -> 8742.9625 | CI12: =MEDIAN(BC7:BC370) -> 9283.562 | CJ12: =MEDIAN(BD7:BD331) -> 8827.2099 | CK12: =MEDIAN(BE7:BE330) -> 9870.9926
B13: 6 | C13: Berapa peluang seseorang tersebut adalah laki-laki diketahui dia adalah perokok? | J13: non perokok | K13: =1-K12 -> 0.79521674 | AJ13: 6 | AK13: =VLOOKUP(AJ13,kelas_charges[[kelas]:[desc]],4,0) -> 29598 s.d 35293 | AL13: =M32 -> 0.027692308 | AM13: =M46 -> 0.030864198 | AN13: =M60 -> 0.021538462 | AO13: =M74 -> 0.016483516 | AX13: 38711 | AY13: 39611.758 | AZ13: 2775.1921 | BA13: 14451.835 | BD13: 7 | BE13: 7 | BF13: 1 | BG13: 3 | BZ13: skew | CA13: =AP24 -> -1.0241644 | CB13: =AQ24 -> -1.5453925 | CC13: =AR24 -> -1.5231147 | CD13: =AS24 -> 0.16947929 | CG13: skew | CH13: =SKEW(BB7:BB331) -> 1.7519426 | CI13: =SKEW(BC7:BC370) -> 1.2501237 | CJ13: =SKEW(BD7:BD331) -> 1.6503626 | CK13: =SKEW(BE7:BE330) -> 1.4992769
B14: 7 | C14: Bagaimana bentuk distribusi peluang besar tagihan dari tiap-tiap region? | J14: Peluang perempuan/laki-laki adalah perokok | AJ14: 7 | AK14: =VLOOKUP(AJ14,kelas_charges[[kelas]:[desc]],4,0) -> 35293 s.d 40989 | AL14: =M33 -> 0.024615385 | AM14: =M47 -> 0.033950617 | AN14: =M61 -> 0.055384615 | AO14: =M75 -> 0.065934066 | AX14: 35585.576 | AY14: 1137.011 | AZ14: 13770.098 | BA14: 2198.1899 | BD14: 7 | BE14: 1 | BF14: 3 | BG14: 1
C15: - Kurtosis | J15: perempuan ∩ perokok | K15: =COUNTIFS(insurance[smoker],"yes",insurance[sex],"female")/COUNT(insurance[age]) -> 0.085949178 | AJ15: 8 | AK15: =VLOOKUP(AJ15,kelas_charges[[kelas]:[desc]],4,0) -> 40989 s.d 46684 | AL15: =M34 -> 0.024615385 | AM15: =M48 -> 0.030864198 | AN15: =M62 -> 0.012307692 | AO15: =M76 -> 0.054945055 | AX15: 4687.797 | AY15: 14001.134 | AZ15: 1625.4337 | BA15: 39774.276 | BD15: 1 | BE15: 3 | BF15: 1 | BG15: 7
C16: - Skewness | J16: laki-laki ∩ perokok | K16: =COUNTIFS(insurance[smoker],"yes",insurance[sex],"male")/COUNT(insurance[age]) -> 0.11883408 | AJ16: 9 | AK16: =VLOOKUP(AJ16,kelas_charges[[kelas]:[desc]],4,0) -> 46684 s.d 52379 | AL16: =M35 -> 0.0061538462 | AM16: =M49 -> 0.0092592593 | AN16: =M63 -> 0.021538462 | AO16: =M77 -> 0.024725275 | AX16: 51194.559 | AY16: 4949.7587 | AZ16: 15612.193 | BA16: 3046.062 | BD16: 9 | BE16: 1 | BF16: 3 | BG16: 1
J17: Peluang perempuan/laki-laki jika diketahui perokok | AJ17: 10 | AK17: =VLOOKUP(AJ17,kelas_charges[[kelas]:[desc]],4,0) -> 52379 s.d 58075 | AL17: =M36 -> 0.0030769231 | AM17: =M50 -> 0 | AN17: =M64 -> 0.0030769231 | AO17: =M78 -> 0 | AX17: 2302.3 | AY17: 6272.4772 | AZ17: 3556.9223 | BA17: 6079.6715 | BD17: 1 | BE17: 1 | BF17: 1 | BG17: 1
J18: p (perempuan|perokok) | K18: =K15/K$12 -> 0.41970803 | AJ18: 11 | AK18: =VLOOKUP(AJ18,kelas_charges[[kelas]:[desc]],4,0) -> 58075 s.d 63771 | AL18: =M37 -> 0.0030769231 | AM18: =M51 -> 0.0030864198 | AN18: =M65 -> 0 | AO18: =M79 -> 0.0054945055 | AX18: 48173.361 | AY18: 6313.759 | AZ18: 3579.8287 | BA18: 3393.3564 | BD18: 9 | BE18: 1 | BF18: 1 | BG18: 1
J19: p (laki-laki|perokok) | K19: =K16/K$12 -> 0.58029197 | AX19: 20630.284 | AY19: 12629.897 | AZ19: 8059.6791 | BA19: 2211.1307 | BD19: 4 | BE19: 3 | BF19: 2 | BG19: 1
AN20: Class | BB20: 23568.272 | BC20: 38709.176 | BD20: 47496.494 | BE20: 13607.369 | BH20: 4 | BI20: 7 | BJ20: 9 | BK20: 3
AN21: Mean | AP21: =AVERAGEIFS(insurance[charges_class],insurance[region],'Langkah #2'!AP$7) -> 2.4923077 | AQ21: =AVERAGEIFS(insurance[charges_class],insurance[region],'Langkah #2'!AQ$7) -> 2.6944444 | AR21: =AVERAGEIFS(insurance[charges_class],insurance[region],'Langkah #2'!AR$7) -> 2.5138462 | AS21: =AVERAGEIFS(insurance[charges_class],insurance[region],'Langkah #2'!AS$7) -> 2.9505495 | BB21: 1743.214 | BC21: 37742.576 | BD21: 5989.5237 | BE21: 8606.2174 | BH21: 1 | BI21: 7 | BJ21: 1 | BK21: 2
AN22: Modus | AP22: =K27 -> 1 | AQ22: =AP22 -> 1 | AR22: =AQ22 -> 1 | AS22: =AR22 -> 1 | BB22: 14235.072 | BC22: 34303.167 | BD22: 30166.618 | BE22: 6799.458 | BH22: 3 | BI22: 6 | BJ22: 6 | BK22: 1
AN23: Median | BB23: 11741.726 | BC23: 23244.79 | BD23: 4133.6416 | BE23: 2755.021 | BH23: 2 | BI23: 4 | BJ23: 1 | BK23: 1
AN24: Skew | AP24: =SKEW(AP8:AP18) -> -1.0241644 | AQ24: =SKEW(AQ8:AQ18) -> -1.5453925 | AR24: =SKEW(AR8:AR18) -> -1.5231147 | AS24: =SKEW(AS8:AS18) -> 0.16947929 | BB24: 7726.854 | BC24: 4504.6624 | BD24: 14711.744 | BE24: 4441.2131 | BH24: 2 | BI24: 1 | BJ24: 3 | BK24: 1
J25: northwest | BB25: 39836.519 | BC25: 5920.1041 | BD25: 6389.3778 | BE25: 7935.2912 | BH25: 7 | BI25: 1 | BJ25: 1 | BK25: 2
J26: desc | K26: class | L26: freq | M26: peluang | BB26: 11073.176 | BC26: 17663.144 | BD26: 11356.661 | BE26: 30184.937 | BH26: 2 | BI26: 3 | BJ26: 2 | BK26: 6
J27: 1121 s.d 6817 | K27: 1 | L27: =COUNTIFS(insurance[charges_class],Table9124[[#This Row],[class]],insurance[region],'Langkah #2'!$J$25) -> 125 | M27: =Table9124[[#This Row],[freq]]/SUM(Table9124[freq]) -> 0.38461538 | BB27: 47291.055 | BC27: 16577.78 | BD27: 6571.0243 | BE27: 22412.648 | BH27: 9 | BI27: 3 | BJ27: 1 | BK27: 4
J28: 6817 s.d 12512 | K28: 2 | L28: =COUNTIFS(insurance[charges_class],Table9124[[#This Row],[class]],insurance[region],'Langkah #2'!$J$25) -> 97 | M28: =Table9124[[#This Row],[freq]]/SUM(Table9124[freq]) -> 0.29846154 | BB28: 12105.32 | BC28: 11946.626 | BD28: 11033.662 | BE28: 3645.0894 | BH28: 2 | BI28: 2 | BJ28: 2 | BK28: 1
J29: 12512 s.d 18207 | K29: 3 | L29: =COUNTIFS(insurance[charges_class],Table9124[[#This Row],[class]],insurance[region],'Langkah #2'!$J$25) -> 36 | M29: =Table9124[[#This Row],[freq]]/SUM(Table9124[freq]) -> 0.11076923 | BB29: 15820.699 | BC29: 3947.4131 | BD29: 21098.554 | BE29: 21344.847 | BH29: 3 | BI29: 1 | BJ29: 4 | BK29: 4
J30: 18207 s.d 23903 | K30: 4 | L30: =COUNTIFS(insurance[charges_class],Table9124[[#This Row],[class]],insurance[region],'Langkah #2'!$J$25) -> 20 | M30: =Table9124[[#This Row],[freq]]/SUM(Table9124[freq]) -> 0.061538462 | BB30: 6186.127 | BC30: 1532.4697 | BD30: 43578.939 | BE30: 11488.317 | BH30: 1 | BI30: 1 | BJ30: 8 | BK30: 2
J31: 23903 s.d 29598 | K31: 5 | L31: =COUNTIFS(insurance[charges_class],Table9124[[#This Row],[class]],insurance[region],'Langkah #2'!$J$25) -> 18 | M31: =Table9124[[#This Row],[freq]]/SUM(Table9124[freq]) -> 0.055384615 | BB31: 5003.853 | BC31: 37165.164 | BD31: 8026.6666 | BE31: 30259.996 | BH31: 1 | BI31: 7 | BJ31: 2 | BK31: 6
J32: 29598 s.d 35293 | K32: 6 | L32: =COUNTIFS(insurance[charges_class],Table9124[[#This Row],[class]],insurance[region],'Langkah #2'!$J$25) -> 9 | M32: =Table9124[[#This Row],[freq]]/SUM(Table9124[freq]) -> 0.027692308 | BB32: 2331.519 | BC32: 2026.9741 | BD32: 11082.577 | BE32: 1705.6245 | BH32: 1 | BI32: 1 | BJ32: 2 | BK32: 1
J33: 35293 s.d 40989 | K33: 7 | L33: =COUNTIFS(insurance[charges_class],Table9124[[#This Row],[class]],insurance[region],'Langkah #2'!$J$25) -> 8 | M33: =Table9124[[#This Row],[freq]]/SUM(Table9124[freq]) -> 0.024615385 | BB33: 11881.358 | BC33: 3766.8838 | BD33: 10942.132 | BE33: 39556.495 | BH33: 2 | BI33: 1 | BJ33: 2 | BK33: 7
J34: 40989 s.d 46684 | K34: 8 | L34: =COUNTIFS(insurance[charges_class],Table9124[[#This Row],[class]],insurance[region],'Langkah #2'!$J$25) -> 8 | M34: =Table9124[[#This Row],[freq]]/SUM(Table9124[freq]) -> 0.024615385 | BB34: 4646.759 | BC34: 10226.284 | BD34: 5729.0053 | BE34: 3385.3992 | BH34: 1 | BI34: 2 | BJ34: 1 | BK34: 1
J35: 46684 s.d 52379 | K35: 9 | L35: =COUNTIFS(insurance[charges_class],Table9124[[#This Row],[class]],insurance[region],'Langkah #2'!$J$25) -> 2 | M35: =Table9124[[#This Row],[freq]]/SUM(Table9124[freq]) -> 0.0061538462 | BB35: 7740.337 | BC35: 30942.192 | BD35: 17560.38 | BE35: 12815.445 | BH35: 2 | BI35: 6 | BJ35: 3 | BK35: 3
J36: 52379 s.d 58075 | K36: 10 | L36: =COUNTIFS(insurance[charges_class],Table9124[[#This Row],[class]],insurance[region],'Langkah #2'!$J$25) -> 1 | M36: =Table9124[[#This Row],[freq]]/SUM(Table9124[freq]) -> 0.0030769231 | BB36: 17081.08 | BC36: 2867.1196 | BD36: 3877.3043 | BE36: 13616.359 | BH36: 3 | BI36: 1 | BJ36: 1 | BK36: 3
J37: 58075 s.d 63771 | K37: 11 | L37: =COUNTIFS(insurance[charges_class],Table9124[[#This Row],[class]],insurance[region],'Langkah #2'!$J$25) -> 1 | M37: =Table9124[[#This Row],[freq]]/SUM(Table9124[freq]) -> 0.0030769231 | BB37: 9634.538 | BC37: 47055.532 | BD37: 10825.254 | BE37: 2457.2112 | BH37: 2 | BI37: 9 | BJ37: 2 | BK37: 1
BB38: 6082.405 | BC38: 11381.325 | BD38: 2404.7338 | BE38: 27375.905 | BH38: 1 | BI38: 2 | BJ38: 1 | BK38: 5
J39: northeast | BB39: 11163.568 | BC39: 19107.78 | BD39: 6686.4313 | BE39: 3490.5491 | BH39: 2 | BI39: 4 | BJ39: 1 | BK39: 1
J40: desc | K40: class | L40: freq | M40: peluang | BB40: 1261.442 | BC40: 8601.3293 | BD40: 2257.4752 | BE40: 6334.3435 | BH40: 1 | BI40: 2 | BJ40: 1 | BK40: 1
J41: 1121 s.d 6817 | K41: 1 | L41: =COUNTIFS(insurance[charges_class],Table91245[[#This Row],[class]],insurance[region],'Langkah #2'!$J$39) -> 104 | M41: =Table91245[[#This Row],[freq]]/SUM(Table91245[freq]) -> 0.32098765 | BB41: 2166.732 | BC41: 2155.6815 | BD41: 10115.009 | BE41: 19964.746 | BH41: 1 | BI41: 1 | BJ41: 2 | BK41: 4
J42: 6817 s.d 12512 | K42: 2 | L42: =COUNTIFS(insurance[charges_class],Table91245[[#This Row],[class]],insurance[region],'Langkah #2'!$J$39) -> 95 | M42: =Table91245[[#This Row],[freq]]/SUM(Table91245[freq]) -> 0.29320988 | BB42: 1842.519 | BC42: 27322.734 | BD42: 32734.186 | BE42: 7077.1894 | BH42: 1 | BI42: 5 | BJ42: 6 | BK42: 2
J43: 12512 s.d 18207 | K43: 3 | L43: =COUNTIFS(insurance[charges_class],Table91245[[#This Row],[class]],insurance[region],'Langkah #2'!$J$39) -> 50 | M43: =Table91245[[#This Row],[freq]]/SUM(Table91245[freq]) -> 0.15432099 | BB43: 10450.552 | BC43: 18972.495 | BD43: 1632.5645 | BE43: 15518.18 | BH43: 2 | BI43: 4 | BJ43: 1 | BK43: 3
J44: 18207 s.d 23903 | K44: 4 | L44: =COUNTIFS(insurance[charges_class],Table91245[[#This Row],[class]],insurance[region],'Langkah #2'!$J$39) -> 26 | M44: =Table91245[[#This Row],[freq]]/SUM(Table91245[freq]) -> 0.080246914 | BB44: 5152.134 | BC44: 5138.2567 | BD44: 2045.6852 | BE44: 10407.086 | BH44: 1 | BI44: 1 | BJ44: 1 | BK44: 2
...

Sheet all
A1: age | D1: bmi | G1: charges | M1: count | N1: peluang
L2: perokok | M2: =COUNTIF(insurance[smoker],"yes") -> 274 | N2: =M2/M$4 -> 0.20478326
A3: Mean | B3: 39.207025 | D3: Mean | E3: 30.663397 | G3: Mean | H3: 13270.422 | L3: non perokok | M3: =COUNTIF(insurance[smoker],"no") -> 1064 | N3: =M3/M$4 -> 0.79521674
A4: Standard Error | B4: 0.38410242 | D4: Standard Error | E4: 0.16671423 | G4: Standard Error | H4: 331.06745 | L4: Total | M4: =SUM(M2:M3) -> 1338 | N4: =SUM(N2:N3) -> 1
A5: Median | B5: 39 | D5: Median | E5: 30.4 | G5: Median | H5: 9382.033
A6: Mode | B6: 18 | D6: Mode | E6: 32.3 | G6: Mode | H6: 1639.5631 | M6: count | N6: peluang
A7: Standard Deviation | B7: 14.04996 | D7: Standard Deviation | E7: 6.0981869 | G7: Standard Deviation | H7: 12110.011 | L7: female | M7: =COUNTIF(insurance[sex],"female") -> 662 | N7: =M7/M$9 -> 0.49476831
A8: Sample Variance | B8: 197.40139 | D8: Sample Variance | E8: 37.187884 | G8: Sample Variance | H8: 1.4665237e+08 | L8: male | M8: =COUNTIF(insurance[sex],"male") -> 676 | N8: =M8/M$9 -> 0.50523169
A9: Kurtosis | B9: -1.2450877 | D9: Kurtosis | E9: -0.050731531 | G9: Kurtosis | H9: 1.6062987 | L9: Total | M9: =SUM(M7:M8) -> 1338 | N9: =SUM(N7:N8) -> 1
A10: Skewness | B10: 0.055672516 | D10: Skewness | E10: 0.28404711 | G10: Skewness | H10: 1.5158797
A11: Range | B11: 46 | D11: Range | E11: 37.17 | G11: Range | H11: 62648.554 | M11: count | N11: peluang
A12: Minimum | B12: 18 | D12: Minimum | E12: 15.96 | G12: Minimum | H12: 1121.8739 | L12: female ∩ perokok | M12: =COUNTIFS(insurance[sex],"female",insurance[smoker],"yes") -> 115 | N12: =M12/H15 -> 0.085949178
A13: Maximum | B13: 64 | D13: Maximum | E13: 53.13 | G13: Maximum | H13: 63770.428 | L13: male ∩ perokok | M13: =COUNTIFS(insurance[sex],"male",insurance[smoker],"yes") -> 159 | N13: =M13/H15 -> 0.11883408
A14: Sum | B14: 52459 | D14: Sum | E14: 41027.625 | G14: Sum | H14: 17755825
A15: Count | B15: 1338 | D15: Count | E15: 1338 | G15: Count | H15: 1338
A16: Largest(1) | B16: 64 | D16: Largest(1) | E16: 53.13 | G16: Largest(1) | H16: 63770.428 | M16: peluang
A17: Smallest(1) | B17: 18 | D17: Smallest(1) | E17: 15.96 | G17: Smallest(1) | H17: 1121.8739 | L17: female| perokok | M17: =N12/N$2 -> 0.41970803
A18: Confidence Level(095%) | B18: 0.75350904 | D18: Confidence Level(095%) | E18: 0.32704996 | G18: Confidence Level(095%) | H18: 649.46823 | L18: male | perokok | M18: =N13/N$2 -> 0.58029197
L20: tagihan tertinggi | M20: =INDEX(insurance[sex],MATCH(H13,insurance[charges],0),1) -> female

Sheet Langkah #3
A1: Langkah #2 - Analisa Variabel Kontinu
A2: No | B2: Item | C2: Hasil | D2: Keterangan
A3: 1 | B3: Mana yang lebih mungkin terjadi : a. Seseorang dengan BMI diatas 25 mendapatkan tagihan kesehatan diatas 16.7k, atau b. Seseorang dengan BMI dibawah 25 mendapatkan tagihan kesehatan diatas 16.7k
A4: 2 | B4: Mana yang lebih mungkin terjadi : a. Seseorang perokok dengan BMI diatas 25 mendapatkan tagihan kesehatan diatas 16.7k, atau b. Seseorang non perokok dengan BMI diatas 25 mendapatkan tagihan kesehatan diatas 16.7k | C4: perokok & bmi>25
H9: perokok | I9: non perokok | J9: total
G10: n(flag perokok ∩ bmi>25) | H10: =COUNTIFS(insurance[bmi],">"&25,insurance[smoker],"yes") -> 219 | I10: =COUNTIFS(insurance[bmi],">"&25,insurance[smoker],"no") -> 872 | J10: =H10+I10 -> 1091
G11: Peluang pengguna dengan bmi > 25 | H11: =H10/SUM(H10:I10) -> 0.20073327 | I11: =1-H11 -> 0.79926673 | J11: =H11+I11 -> 1
J12: =H13+I13 -> 283
G13: n(charges>16,7K ∩ flag perokok ∩ bmi>25) | H13: =COUNTIFS(insurance[bmi],">"&25,insurance[smoker],"yes",insurance[charges_16,7K],1) -> 215 | I13: =COUNTIFS(insurance[bmi],">"&25,insurance[smoker],"no",insurance[charges_16,7K],1) -> 68 | J13: =H14+I14 -> 1.0597168
G14: p(charges>16,7K | (flag perokok ∩ bmi>25)) | H14: =H13/H10 -> 0.98173516 | I14: =I13/I10 -> 0.077981651

Sheet Langkah #4
B2: Langkah #4 - Analisa Korelasi Variabel
C5: charges | D5: ages | E5: smoker | F5: region | G5: sex | H5: bmi | I5: child
B6: charges | C6: 1
B7: ages | C7: 0.29900819 | D7: 1
B8: smoker | C8: 0.78725143 | D8: -0.025018752 | E8: 1
B9: region | C9: 0.056992781 | D9: -0.0052116897 | E9: 0.053929632 | F9: 1
B10: sex | C10: 0.057292062 | D10: -0.020855872 | E10: 0.076184817 | F10: 0.016120988 | G10: 1
B11: bmi | C11: 0.19834097 | D11: 0.10927188 | E11: 0.0037504259 | F11: 0.26182888 | G11: 0.046371151 | H11: 1
B12: child | C12: 0.067998227 | D12: 0.042468999 | E12: 0.0076731203 | F12: -0.019257217 | G12: 0.017162978 | H12: 0.012758901 | I12: 1

Sheet Langkah #5
B2: Langkah #5 - Pengujian Hipotesa | K2: Tagihan kesehatan perokok lebih tinggi daripada tagihan kesehatan non perokok
B4: 1. Tagihan kesehatan perokok lebih tinggi daripada tagihan kesehatan non perokok | K4: 1. Menentukan hipotesis dan taraf significance
B5: 2. Tagihan kesehatan dengan BMI diatas 25 lebih tinggi daripada tagihan kesehatan | K5: H0 : Nilai rata-rata tagihan perokok <= nilai rata-rata tagihan non perokok
B6: dengan BMI dibawah 25 | K6: H1 : Nilai rata-rata tagihan perokok > nilai rata-rata tagihan non perokok
B7: 3. Tagihan kesehatan laki-laki lebih besar dari perempuan | K7: Nilai α (taraf significance) = | N7: 0.05
K9: 2. Tentukan statistik uji yang digunakan
K10: Dikarenakan standard deviasi populasi tidak diketahui maka digunakan uji t test
K12: 3. Menentukan aturan pengambilan keputusan
K13: - Dikarenakan H1 mengandung > maka dilakukan uji kanan
K14: - Dimana tolak H0 jika hasil uji statistik > nilai kritis
K16: menentukan nilai kritis atas significance = 0,05 dapat dilihat dari table
K17: sehingga nilai kritis = 1.645
K18: hitung nilai kritis manual
L20: perokok | M20: non perokok
K21: n | L21: =COUNTIFS(insurance[smoker],"yes") -> 274 | M21: =COUNTIFS(insurance[smoker],"no") -> 1064
K22: df | L22: =L21-1 -> 273 | M22: =M21-1 -> 1063
K23: α | L23: =N7 -> 0.05 | M23: =N7 -> 0.05
K24: nilai kritis | L24: =TINV(L23,L22) -> 1.9686916 | M24: =TINV(M23,M22) -> 1.9621982
K26: 4. Hitung statistic
L28: perokok | M28: non perokok | N28: non perokok (reduce row)
K29: 𝑥 ̅ | L29: =AVERAGEIFS(insurance[charges],insurance[smoker],"Yes") -> 32050.232 | M29: =AVERAGEIFS(insurance[charges],insurance[smoker],"no") -> 8434.2683 | N29: =AVERAGE('5.1'!C2:C275) -> 8460.7859
K30: σ | L30: {=STDEV(IF(insurance[smoker]="yes",insurance[charges]))} -> 11541.547 | M30: {=STDEV(IF(insurance[smoker]="no",insurance[charges]))} -> 5993.7818 | N30: =STDEV('5.1'!C2:C275) -> 6048.0131
K31: n | L31: =L21 -> 274 | M31: =M21 -> 1064 | N31: =L31 -> 274
K32: σ / n^1/2 | L32: =L30/L31^(1/2) -> 697.25036 | M32: =M30/M31^(1/2) -> 183.75117 | N32: =N30/N31^(1/2) -> 365.37384
K34: t-hitung | M34: =(L29-M29)/(L32+M32) -> 26.805814
K35: t-hitung (reduce row) | M35: =(L29-N29)/(L32+N32) -> 22.199237
K37: karena t-hitung > nilai kritis maka tolak H0
K39: P-value | L39: ='5.1'!G11 -> 1.5988377e-86
K40: jika p-value < α maka total H0
K43: 2. Tagihan kesehatan dengan BMI diatas 25 lebih tinggi daripada tagihan kesehatan dengan BMI dibawah 25
K45: 1. Menentukan hipotesis dan taraf significance
K46: H0 : Nilai rata-rata tagihan bmi di atas 25 <= nilai rata-rata tagihan bmi di bawah 25
K47: H1 : Nilai rata-rata tagihan bmi di atas 25 > nilai rata-rata tagihan bmi di bawah 25
K48: Nilai α (taraf significance) = | N48: 0.05
K50: 2. Tentukan statistik uji yang digunakan
K51: Dikarenakan standard deviasi populasi tidak diketahui maka digunakan uji t test
K53: 3. Menentukan aturan pengambilan keputusan
K54: - Dikarenakan H1 mengandung > maka dilakukan uji kanan
K55: - Dimana tolak H0 jika hasil uji statistik > nilai kritis
K57: menentukan nilai kritis atas significance = 0,05 dapat dilihat dari table
...

Sheet 5.1
B1: perokok | C1: non perokok
B2: 16884.924 | C2: 1725.5523 | F2: t-Test: Paired Two Sample for Means
B3: 27808.725 | C3: 4449.462 | G3: perokok | H3: non perokok
B4: 39611.758 | C4: 21984.471 | F4: Mean | G4: 32050.232 | H4: 8460.7859
B5: 36837.467 | C5: 3866.8552 | F5: Variance | G5: 1.3320731e+08 | H5: 36578463
B6: 37701.877 | C6: 3756.6216 | F6: Observations | G6: 274 | H6: 274
B7: 38711 | C7: 8240.5896 | F7: Pearson Correlation | G7: -0.057382398
B8: 35585.576 | C8: 7281.5056 | F8: Hypothesized Mean Difference | G8: 0
B9: 51194.559 | C9: 6406.4107 | F9: df | G9: 273
B10: 39774.276 | C10: 28923.137 | F10: t Stat | G10: 29.284048
B11: 48173.361 | C11: 2721.3208 | F11: P(T<=t) one-tail | G11: 1.5988377e-86
B12: 38709.176 | C12: 1826.843 | F12: t Critical one-tail | G12: 1.6504543
B13: 23568.272 | C13: 11090.718 | F13: P(T<=t) two-tail | G13: 3.1976754e-86
B14: 37742.576 | C14: 1837.237 | F14: t Critical two-tail | G14: 1.9686916
B15: 47496.494 | C15: 10797.336
B16: 34303.167 | C16: 2395.1716
B17: 23244.79 | C17: 10602.385
B18: 14711.744 | C18: 13228.847
B19: 17663.144 | C19: 4149.736
B20: 16577.78 | C20: 1137.011
B21: 37165.164 | C21: 6203.9017
B22: 39836.519 | C22: 14001.134
B23: 21098.554 | C23: 14451.835
B24: 43578.939 | C24: 12268.632
B25: 30184.937 | C25: 2775.1921
B26: 47291.055 | C26: 2198.1899
... B275: 29141.36 | C275: 14133.038
C276: 24603.048
C277: 8944.1151
C278: 9620.3307
C279: 1837.2819
C280: 1607.5101
C281: 10043.249
C282: 4751.07
C283: 2597.779
C284: 3180.5101
C285: 9778.3472
C286: 13430.265
C287: 8017.0612
... C1065: 2007.945

Sheet 5.2
B1: bmi>25 | C1: bmi<=25 | F1: t-Test: Paired Two Sample for Means | J1: t-Test: Two-Sample Assuming Unequal Variances
B2: 16884.924 | C2: 21984.471
B3: 1725.5523 | C3: 1837.237 | G3: bmi>25 | H3: bmi<=25 | K3: bmi>25 | L3: bmi<=25
B4: 4449.462 | C4: 2395.1716 | F4: Mean | G4: 14038.567 | H4: 10284.29 | J4: Mean | K4: 13946.476 | L4: 10284.29
B5: 3866.8552 | C5: 14451.835 | F5: Variance | G5: 1.7587168e+08 | H5: 56167440 | J5: Variance | K5: 1.6473018e+08 | L5: 56167440
B6: 3756.6216 | C6: 2775.1921 | F6: Observations | G6: 247 | H6: 247 | J6: Observations | K6: 1091 | L6: 247
B7: 8240.5896 | C7: 1625.4337 | F7: Pearson Correlation | G7: 0.08271113 | J7: Hypothesized Mean Difference | K7: 0
B8: 7281.5056 | C8: 2302.3 | F8: Hypothesized Mean Difference | G8: 0 | J8: df | K8: 619
B9: 6406.4107 | C9: 6272.4772 | F9: df | G9: 246 | J9: t Stat | K9: 5.9534864
B10: 28923.137 | C10: 12629.897 | F10: t Stat | G10: 4.0183946 | J10: P(T<=t) one-tail | K10: 2.1994657e-09
B11: 2721.3208 | C11: 23244.79 | F11: P(T<=t) one-tail | G11: 3.8961031e-05 | J11: t Critical one-tail | K11: 1.647319
B12: 27808.725 | C12: 30166.618 | F12: t Critical one-tail | G12: 1.6510713 | J12: P(T<=t) two-tail | K12: 4.3989313e-09
B13: 1826.843 | C13: 14711.744 | F13: P(T<=t) two-tail | G13: 7.7922061e-05 | J13: t Critical two-tail | K13: 1.9638038
B14: 11090.718 | C14: 17663.144 | F14: t Critical two-tail | G14: 1.9696542
B15: 39611.758 | C15: 16577.78
B16: 10797.336 | C16: 21098.554
B17: 10602.385 | C17: 10942.132
B18: 36837.467 | C18: 22412.648
B19: 13228.847 | C19: 15820.699
B20: 4149.736 | C20: 6686.4313
B21: 1137.011 | C21: 1705.6245
B22: 37701.877 | C22: 32734.186
B23: 6203.9017 | C23: 13616.359
B24: 14001.134 | C24: 27375.905
B25: 12268.632 | C25: 5125.2157
B26: 38711 | C26: 19964.746
... B248: 2156.7518 | C248: 22395.744
B249: 3906.127
B250: 16297.846
B251: 21978.677
B252: 38746.355
B253: 9249.4952
B254: 6746.7425
B255: 12265.507
B256: 4349.462
B257: 12646.207
B258: 19442.354
B259: 20177.671
B260: 4151.0287
... B1092: 29141.36

Sheet 5.3
B1: male | C1: female | F1: t-Test: Paired Two Sample for Means | K1: t-Test: Two-Sample Assuming Unequal Variances
B2: 1725.5523 | C2: 16884.924
B3: 4449.462 | C3: 3756.6216 | G3: male | H3: female | L3: male | M3: female
B4: 21984.471 | C4: 8240.5896 | F4: Mean | G4: 14033.661 | H4: 12569.579 | K4: Mean | L4: 13956.751 | M4: 12569.579
B5: 3866.8552 | C5: 7281.5056 | F5: Variance | G5: 1.7058877e+08 | H5: 1.2384805e+08 | K5: Variance | L5: 1.6824751e+08 | M5: 1.2384805e+08
B6: 6406.4107 | C6: 28923.137 | F6: Observations | G6: 662 | H6: 662 | K6: Observations | L6: 676 | M6: 662
B7: 2721.3208 | C7: 27808.725 | F7: Pearson Correlation | G7: 0.019555707 | K7: Hypothesized Mean Difference | L7: 0
B8: 1826.843 | C8: 11090.718 | F8: Hypothesized Mean Difference | G8: 0 | K8: df | L8: 1313
B9: 39611.758 | C9: 10797.336 | F9: df | G9: 661 | K9: t Stat | L9: 2.1008878
B10: 1837.237 | C10: 13228.847 | F10: t Stat | G10: 2.216828 | K10: P(T<=t) one-tail | L10: 0.017920534
B11: 2395.1716 | C11: 4149.736 | F11: P(T<=t) one-tail | G11: 0.013487204 | K11: t Critical one-tail | L11: 1.646015
B12: 10602.385 | C12: 37701.877 | F12: t Critical one-tail | G12: 1.6471621 | K12: P(T<=t) two-tail | L12: 0.035841067
B13: 36837.467 | C13: 14001.134 | F13: P(T<=t) two-tail | G13: 0.026974408 | K13: t Critical two-tail | L13: 1.9617724
B14: 1137.011 | C14: 14451.835 | F14: t Critical two-tail | G14: 1.9635594
B15: 6203.9017 | C15: 12268.632
B16: 2775.1921 | C16: 2198.1899
B17: 38711 | C17: 4687.797
B18: 35585.576 | C18: 15612.193
B19: 13770.098 | C19: 3046.062
B20: 51194.559 | C20: 4949.7587
B21: 1625.4337 | C21: 6313.759
B22: 2302.3 | C22: 3393.3564
B23: 39774.276 | C23: 3556.9223
B24: 48173.361 | C24: 12629.897
B25: 6272.4772 | C25: 2211.1307
B26: 6079.6715 | C26: 3579.8287
... B663: 21472.479 | C663: 29141.36
B664: 6875.961
B665: 6940.9099
B666: 4536.259
B667: 11272.331
B668: 1163.4627
B669: 19496.719
B670: 5425.0234
B671: 28101.333
B672: 12981.346
B673: 4239.8926
B674: 13143.337
B675: 9377.9047
... B677: 10600.548

Sheet param
B2: kelas | C2: Lower | D2: Upper | E2: desc | F2: round lower | G2: round upper | I2: wilayah | J2: alias | L2: bmi bawah | M2: bmi atas | N2: bmi name
B3: 1 | C3: 1121.8739 | D3: 6817.197 | E3: =CONCATENATE(kelas_charges[[#This Row],[round lower]]," s.d ",kelas_charges[[#This Row],[round upper]]) -> 1121 s.d 6817 | F3: =ROUNDDOWN(kelas_charges[[#This Row],[Lower]],0) -> 1121 | G3: =ROUNDDOWN(kelas_charges[[#This Row],[Upper]],0) -> 6817 | I3: northwest | J3: 1 | L3: 0 | M3: 18.5 | N3: Underweight
B4: 2 | C4: =D3 -> 6817.197 | D4: 12512.52 | E4: =CONCATENATE(kelas_charges[[#This Row],[round lower]]," s.d ",kelas_charges[[#This Row],[round upper]]) -> 6817 s.d 12512 | F4: =ROUNDDOWN(kelas_charges[[#This Row],[Lower]],0) -> 6817 | G4: =ROUNDDOWN(kelas_charges[[#This Row],[Upper]],0) -> 12512 | I4: northeast | J4: 2 | L4: =M3 -> 18.5 | M4: 23 | N4: Normal
B5: 3 | C5: =D4 -> 12512.52 | D5: 18207.843 | E5: =CONCATENATE(kelas_charges[[#This Row],[round lower]]," s.d ",kelas_charges[[#This Row],[round upper]]) -> 12512 s.d 18207 | F5: =ROUNDDOWN(kelas_charges[[#This Row],[Lower]],0) -> 12512 | G5: =ROUNDDOWN(kelas_charges[[#This Row],[Upper]],0) -> 18207 | I5: southwest | J5: 3 | L5: =M4 -> 23 | M5: 25 | N5: Overweight
B6: 4 | C6: =D5 -> 18207.843 | D6: 23903.166 | E6: =CONCATENATE(kelas_charges[[#This Row],[round lower]]," s.d ",kelas_charges[[#This Row],[round upper]]) -> 18207 s.d 23903 | F6: =ROUNDDOWN(kelas_charges[[#This Row],[Lower]],0) -> 18207 | G6: =ROUNDDOWN(kelas_charges[[#This Row],[Upper]],0) -> 23903 | I6: southeast | J6: 4 | L6: =M5 -> 25 | M6: 30 | N6: Obesitas I
B7: 5 | C7: =D6 -> 23903.166 | D7: 29598.489 | E7: =CONCATENATE(kelas_charges[[#This Row],[round lower]]," s.d ",kelas_charges[[#This Row],[round upper]]) -> 23903 s.d 29598 | F7: =ROUNDDOWN(kelas_charges[[#This Row],[Lower]],0) -> 23903 | G7: =ROUNDDOWN(kelas_charges[[#This Row],[Upper]],0) -> 29598 | L7: =M6 -> 30 | M7: 100 | N7: Obesitas II
B8: 6 | C8: =D7 -> 29598.489 | D8: 35293.813 | E8: =CONCATENATE(kelas_charges[[#This Row],[round lower]]," s.d ",kelas_charges[[#This Row],[round upper]]) -> 29598 s.d 35293 | F8: =ROUNDDOWN(kelas_charges[[#This Row],[Lower]],0) -> 29598 | G8: =ROUNDDOWN(kelas_charges[[#This Row],[Upper]],0) -> 35293
B9: 7 | C9: =D8 -> 35293.813 | D9: 40989.136 | E9: =CONCATENATE(kelas_charges[[#This Row],[round lower]]," s.d ",kelas_charges[[#This Row],[round upper]]) -> 35293 s.d 40989 | F9: =ROUNDDOWN(kelas_charges[[#This Row],[Lower]],0) -> 35293 | G9: =ROUNDDOWN(kelas_charges[[#This Row],[Upper]],0) -> 40989
B10: 8 | C10: =D9 -> 40989.136 | D10: 46684.459 | E10: =CONCATENATE(kelas_charges[[#This Row],[round lower]]," s.d ",kelas_charges[[#This Row],[round upper]]) -> 40989 s.d 46684 | F10: =ROUNDDOWN(kelas_charges[[#This Row],[Lower]],0) -> 40989 | G10: =ROUNDDOWN(kelas_charges[[#This Row],[Upper]],0) -> 46684
B11: 9 | C11: =D10 -> 46684.459 | D11: 52379.782 | E11: =CONCATENATE(kelas_charges[[#This Row],[round lower]]," s.d ",kelas_charges[[#This Row],[round upper]]) -> 46684 s.d 52379 | F11: =ROUNDDOWN(kelas_charges[[#This Row],[Lower]],0) -> 46684 | G11: =ROUNDDOWN(kelas_charges[[#This Row],[Upper]],0) -> 52379
B12: 10 | C12: =D11 -> 52379.782 | D12: 58075.105 | E12: =CONCATENATE(kelas_charges[[#This Row],[round lower]]," s.d ",kelas_charges[[#This Row],[round upper]]) -> 52379 s.d 58075 | F12: =ROUNDDOWN(kelas_charges[[#This Row],[Lower]],0) -> 52379 | G12: =ROUNDDOWN(kelas_charges[[#This Row],[Upper]],0) -> 58075
B13: 11 | C13: =D12 -> 58075.105 | D13: 63771 | E13: =CONCATENATE(kelas_charges[[#This Row],[round lower]]," s.d ",kelas_charges[[#This Row],[round upper]]) -> 58075 s.d 63771 | F13: =ROUNDDOWN(kelas_charges[[#This Row],[Lower]],0) -> 58075 | G13: =ROUNDDOWN(kelas_charges[[#This Row],[Upper]],0) -> 63771

Sheet insurance olah help
A1: age | B1: sex | C1: bmi | D1: children | E1: smoker | F1: region | G1: charges | H1: charges_class | I1: desc_charges_class | J1: charges_class2 | K1: charges_correl | L1: ages_correl | M1: smoker_correl | N1: smo | O1: cha | P1: bmi name | Q1: cha2 | R1: smo2 | S1: bmi2 | T1: age2 | U1: bmi3 | V1: class | W1: region_correl | X1: sex_correl | Y1: bmi_correl | Z1: child_correl
A2: 19 | B2: female | C2: 27.9 | D2: 0 | E2: yes | F2: southwest | G2: 16884.924 | H2: {=INDEX(kelas_charges[kelas],MATCH(1,(insurance9[[#This Row],[charges]]>=kelas_charges[Lower])*(insurance9[[#This Row],[charges]]<kelas_charges[Upper]),0),1)} -> 3 | I2: {=INDEX(kelas_charges[desc],MATCH(1,(insurance9[[#This Row],[charges]]>=kelas_charges[Lower])*(insurance9[[#This Row],[charges]]<kelas_charges[Upper]),0),1)} -> 12512 s.d 18207 | J2: =IF(insurance9[[#This Row],[charges]]>16700,1,0) -> 1 | K2: =insurance9[[#This Row],[charges]] -> 16884.924 | L2: =insurance9[[#This Row],[age]] -> 19 | M2: =IF(insurance9[[#This Row],[smoker]]="yes",1,0) -> 1 | N2: =IF(insurance9[[#This Row],[smoker]]="yes","Perokok","Non Perokok") -> Perokok | O2: =insurance9[[#This Row],[charges]] -> 16884.924 | P2: {=INDEX(bmi[bmi name],MATCH(1,(insurance9[[#This Row],[bmi]]<bmi[bmi atas])*(insurance9[[#This Row],[bmi]]>=bmi[bmi bawah]),0),0)} -> Obesitas I | Q2: =insurance9[[#This Row],[cha]] -> 16884.924 | R2: =insurance9[[#This Row],[smo]] -> Perokok | S2: =insurance9[[#This Row],[bmi]] -> 27.9 | T2: =insurance9[[#This Row],[age]] -> 19 | U2: =insurance9[[#This Row],[bmi2]] -> 27.9 | V2: =insurance9[[#This Row],[charges_class]] -> 3 | W2: =VLOOKUP(insurance9[[#This Row],[region]],Table2[],2,0) -> 3 | X2: =IF(insurance9[[#This Row],[sex]]="female",0,1) -> 0 | Y2: =insurance9[[#This Row],[bmi]] -> 27.9 | Z2: =insurance9[[#This Row],[children]] -> 0
